<?xml version="1.0"?>
<robot name="Robocov">

  <!-- Base -->
  <link name="base_footprint"/>

  <link name="base_link">
    <visual>
      <geometry>
        <box size="0.843 0.61 0.25"/>
      </geometry>
      <origin xyz="0.2065 0 0.125"/>
      <material name="gray">
        <color rgba="0.6 0.6 0.6 1.0"/>
      </material>
    </visual>
  </link>

  <!-- Ruedas diferenciales -->
  <link name="wheel_left_link">
    <visual>
      <origin xyz="0 -0.3 0.08" rpy="0 1.5708 0"/>
      <geometry>
        <cylinder radius="0.08" length="0.05"/>
      </geometry>
      <material name="black">
        <color rgba="0.1 0.1 0.1 1.0"/>
      </material>
    </visual>
  </link>

  <joint name="wheel_left_joint" type="continuous">
    <parent link="base_link"/>
    <child link="wheel_left_link"/>
    <origin xyz="0 0.3 0"/>
    <axis xyz="0 1 0"/>
  </joint>

  <link name="wheel_right_link">
    <visual>
      <origin xyz="0 0.3 0.08" rpy="0 1.5708 0"/>
      <geometry>
        <cylinder radius="0.08" length="0.05"/>
      </geometry>
      <material name="black">
        <color rgba="0.1 0.1 0.1 1.0"/>
      </material>
    </visual>
  </link>

  <joint name="wheel_right_joint" type="continuous">
    <parent link="base_link"/>
    <child link="wheel_right_link"/>
    <origin xyz="0 -0.3 0"/>
    <axis xyz="0 1 0"/>
  </joint>

  <!-- Ruedas locas -->
  <link name="caster_fl_link"/>
  <joint name="caster_fl_joint" type="fixed">
    <parent link="base_link"/>
    <child link="caster_fl_link"/>
    <origin xyz="0.53 0.25 0.0"/>
  </joint>

  <link name="caster_fr_link"/>
  <joint name="caster_fr_joint" type="fixed">
    <parent link="base_link"/>
    <child link="caster_fr_link"/>
    <origin xyz="0.53 -0.25 0.0"/>
  </joint>

  <!-- IMU -->
  <link name="bno055"/>
  <joint name="imu_joint" type="fixed">
    <parent link="base_link"/>
    <child link="bno055"/>
    <origin xyz="0 0 0.353"/>
  </joint>

  <!-- Cámara -->
  <link name="camera"/>
  <joint name="camera_joint" type="fixed">
    <parent link="base_link"/>
    <child link="camera"/>
    <origin xyz="0.09 0 0.548"/>
  </joint>

  <!-- LiDAR -->
  <link name="laser"/>
  <joint name="lidar_joint" type="fixed">
    <parent link="base_link"/>
    <child link="laser"/>
    <origin xyz="0 0 0.624" rpy="0 0 3.1416"/>
  </joint>

  <!-- Unión base_link -> base_footprint -->
  <joint name="base_footprint_joint" type="fixed">
    <parent link="base_link"/>
    <child link="base_footprint"/>
    <origin xyz="0 0 -0.08"/>
  </joint>

</robot>